Workbook

Sheet Cover
B2: MEGALODOME GOLF — CHICAGO WEST
B3: Investor Pro-Forma · Megalodome Golf Equity Fund I
B4: Flagship — Oswego, Illinois (≈45 mi west of downtown Chicago)
A6: HEADLINE TERMS (NEW STRUCTURE — illustrative, pending counsel)
B7: Total project capitalization | C7: $77.0M
B8: Equity raise (3 tranches) | C8: $25.0M · Fund $10M / Membership $10M / Outside $5M
B9: Debt | C9: $52.0M · $40M bank @ 8.40% + $12M lease @ 8.50%
B10: Preferred return (Fund + Membership) | C10: 10% p.a., cumulative, non-compounded
B11: Above-pref split (Manager / investor pool) | C11: 50% / 50%
B12: Outside direct equity | C12: 15% of Chicago West
B13: Modeled blended investor IRR (5-yr) | C13: =Returns!C30 -> 0.19742363
B14: Modeled blended investor MOIC | C14: =Returns!D30 -> 2.3538713
B15: Exit basis / target opening | C15: Yr-5 EBITDA × 9.0x, net of debt · Fall 2027
A17: HOW TO USE THIS MODEL
B18: • Blue figures are inputs you can change; black figures are formulas that recalculate.
B19: • Green figures are links pulling from another tab in this workbook.
B20: • Change any blue assumption (occupancy, price, exit multiple) and Returns + Sensitivity update automatically.
B21: • The two levers that move returns most — Year-5 EBITDA and exit multiple — flow live to IRR and MOIC.
B22: • Figures reflect the restructured capital stack; equity-waterfall splits are illustrative and subject to amended offering documents (Bond Conway) before investor use.
B24: CONFIDENTIAL — FOR ACCREDITED INVESTORS ONLY. This pro-forma contains forward-looking projections that are estimates, not guarantees; actual results will differ. It is not an offer to sell or a solicitation to buy any security. Any offering is made solely through the Confidential Private Placement Memorandum of Megalodome Golf Equity Fund I LLC and its subscription documents under Rule 506(c) of Regulation D. Targeted returns are modeled and depend on assumptions stated herein, several of which remain to be finalized (debt terms, Year-1 occupancy ramp, exit multiple). Consult your own legal, tax and financial advisors.

Sheet Assumptions
B1: ASSUMPTIONS — all blue cells are inputs
B2: Source anchor: Megalodome Chicago West Financial Model, 03/30/2026
A4: OPERATING CALENDAR
B5: Spring / Summer operating days (Apr–Sep) | C5: 183
B6: Fall / Winter operating days (Oct–Mar) | C6: 182
B7: Year-1 (FY2027) revenue realization — partial year / ramp | C7: 0.379
B8: Annual price / revenue growth (FY2029+) | C8: 0.0285
A10: GREEN FEES — course play
C11: Spring/Summer | D11: Fall/Winter
B12: Capacity — players / day at 100% | C12: 420 | D12: 444
B13: Average occupancy | C13: 0.5208 | D13: 0.8958
B14: Average green fee | C14: 80 | D14: 122.5
A16: PRACTICE FACILITY — range / simulators / short game
C17: Spring/Summer | D17: Fall/Winter
B18: Capacity — player-sessions / day at 100% | C18: 880 | D18: 895
B19: Average occupancy | C19: 0.2333 | D19: 0.8
B20: Average price / session | C20: 35 | D20: 62.5
A22: OTHER INCOME & COST STRUCTURE
B23: Other income — FY2028 base (F&B, pro shop, banquet, naming) | C23: 785400
B24: Other income — FY2027 (partial) | C24: 192500
A26: Operating + administrative expense (% of revenue, per year)
C27: 2026 | D27: 2027 | E27: 2028 | F27: 2029 | G27: 2030 | H27: 2031
B28: Operating expense % of revenue | C28: 0 | D28: 0.1708 | E28: 0.2552 | F28: 0.2557 | G28: 0.253 | H28: 0.2517
B29: Administrative expense % of revenue | C29: 0 | D29: 0.2256 | E29: 0.1394 | F29: 0.1313 | G29: 0.1308 | H29: 0.1305
B30: Depreciation & amortization ($) | C30: 0 | D30: 743221 | E30: 2972884 | F30: 2981426 | G30: 2969593 | H30: 2930009
A32: CAPITAL STACK & FINANCING
B33: Fund equity — Class B preferred (Reg D 506(c)) | C33: 10000000
B34: Membership equity — founding members | C34: 10000000
B35: Outside equity — direct stake in Chicago West opco | C35: 5000000
B36: Total equity | C36: =SUM(C33:C35) -> 25000000
B37: Bank senior term loan — principal | C37: 40000000
B38: Bank senior loan interest rate | C38: 0.084
B39: Equipment / leasing facility — principal | C39: 12000000
B40: Leasing facility interest rate | C40: 0.085
B41: Leasing facility term (years, amortizing) | C41: 7
B42: Total debt | C42: =C37+C39 -> 52000000
B43: Total project capitalization | C43: =C36+C42 -> 77000000
A45: RETURN & WATERFALL TERMS
B46: Preferred return rate (Fund + Membership pool) | C46: 0.1
B47: Above-pref split — investor pool (Fund + Membership) | C47: 0.5
...

Sheet Revenue Build
B1: REVENUE BUILD — from units × occupancy × price × days
A3: ANNUAL RUN-RATE (full-year, stabilized)
B4: Segment | C4: Summer | D4: Winter | E4: Full-year
B5: Green fees | C5: =Assumptions!C12*Assumptions!C13*Assumptions!C14*Assumptions!C5 -> 3202295 | D5: =Assumptions!D12*Assumptions!D13*Assumptions!D14*Assumptions!C6 -> 8867506.3 | E5: =C5+D5 -> 12069801
B6: Practice facility | C6: =Assumptions!C18*Assumptions!C19*Assumptions!C20*Assumptions!C5 -> 1314972.1 | D6: =Assumptions!D18*Assumptions!D19*Assumptions!D20*Assumptions!C6 -> 8144500 | E6: =C6+D6 -> 9459472.1
B7: Other income | E7: =Assumptions!C23 -> 785400
B8: Total full-year run-rate | E8: =E5+E6+E7 -> 22314673
A10: REVENUE BY FISCAL YEAR
B11: USD $ | C11: 2026 | D11: 2027 | E11: 2028 | F11: 2029 | G11: 2030 | H11: 2031
B12: Green fees | C12: 0 | D12: =$E$5*Assumptions!C7 -> 4574454.7 | E12: =$E$5 -> 12069801 | F12: =E12*(1+Assumptions!C8) -> 12413791 | G12: =F12*(1+Assumptions!C8) -> 12767584 | H12: =G12*(1+Assumptions!C8) -> 13131460
B13: Practice facility | C13: 0 | D13: =$E$6*Assumptions!C7 -> 3585139.9 | E13: =$E$6 -> 9459472.1 | F13: =E13*(1+Assumptions!C8) -> 9729067.1 | G13: =F13*(1+Assumptions!C8) -> 10006345 | H13: =G13*(1+Assumptions!C8) -> 10291526
B14: Other income | C14: 0 | D14: =Assumptions!C24 -> 192500 | E14: =Assumptions!C23 -> 785400 | F14: =E14*(1+Assumptions!C8) -> 807783.9 | G14: =F14*(1+Assumptions!C8) -> 830805.74 | H14: =G14*(1+Assumptions!C8) -> 854483.7
B15: Total revenue | C15: =SUM(C12:C14) -> 0 | D15: =SUM(D12:D14) -> 8352094.6 | E15: =SUM(E12:E14) -> 22314673 | F15: =SUM(F12:F14) -> 22950642 | G15: =SUM(G12:G14) -> 23604735 | H15: =SUM(H12:H14) -> 24277470
B16: Revenue growth % | C16: n/a | D16: n/a | E16: =E15/D15-1 -> 1.6717458 | F16: =F15/E15-1 -> 0.0285 | G16: =G15/F15-1 -> 0.0285 | H16: =H15/G15-1 -> 0.0285

Sheet P&L
B1: PROJECTED P&L — FY2026–FY2031 (USD)
B3: USD $ | C3: 2026 | D3: 2027 | E3: 2028 | F3: 2029 | G3: 2030 | H3: 2031
B4: Total revenue | C4: ='Revenue Build'!C15 -> 0 | D4: ='Revenue Build'!D15 -> 8352094.6 | E4: ='Revenue Build'!E15 -> 22314673 | F4: ='Revenue Build'!F15 -> 22950642 | G4: ='Revenue Build'!G15 -> 23604735 | H4: ='Revenue Build'!H15 -> 24277470
B5: Operating expenses | C5: =-C4*Assumptions!C28 -> 0 | D5: =-D4*Assumptions!D28 -> -1426537.8 | E5: =-E4*Assumptions!E28 -> -5694704.7 | F5: =-F4*Assumptions!F28 -> -5868479.1 | G5: =-G4*Assumptions!G28 -> -5971997.9 | H5: =-H4*Assumptions!H28 -> -6110639.2
B6: Administrative expenses | C6: =-C4*Assumptions!C29 -> 0 | D6: =-D4*Assumptions!D29 -> -1884232.5 | E6: =-E4*Assumptions!E29 -> -3110665.5 | F6: =-F4*Assumptions!F29 -> -3013419.2 | G6: =-G4*Assumptions!G29 -> -3087499.3 | H6: =-H4*Assumptions!H29 -> -3168209.8
B7: EBITDA | C7: =C4+C5+C6 -> 0 | D7: =D4+D5+D6 -> 5041324.3 | E7: =E4+E5+E6 -> 13509303 | F7: =F4+F5+F6 -> 14068743 | G7: =G4+G5+G6 -> 14545238 | H7: =H4+H5+H6 -> 14998621
B8: EBITDA margin | C8: =IFERROR(C7/C4,"n/a") -> n/a | D8: =IFERROR(D7/D4,"n/a") -> 0.6036 | E8: =IFERROR(E7/E4,"n/a") -> 0.6054 | F8: =IFERROR(F7/F4,"n/a") -> 0.613 | G8: =IFERROR(G7/G4,"n/a") -> 0.6162 | H8: =IFERROR(H7/H4,"n/a") -> 0.6178
B9: Depreciation & amortization | C9: =-Assumptions!C30 -> 0 | D9: =-Assumptions!D30 -> -743221 | E9: =-Assumptions!E30 -> -2972884 | F9: =-Assumptions!F30 -> -2981426 | G9: =-Assumptions!G30 -> -2969593 | H9: =-Assumptions!H30 -> -2930009
B10: EBIT | C10: =C7+C9 -> 0 | D10: =D7+D9 -> 4298103.3 | E10: =E7+E9 -> 10536419 | F10: =F7+F9 -> 11087317 | G10: =G7+G9 -> 11575645 | H10: =H7+H9 -> 12068612
B11: Interest expense (net) | C11: ='Debt & Capital'!C44 -> 0 | D11: ='Debt & Capital'!D44 -> -4380000 | E11: ='Debt & Capital'!E44 -> -4267423.4 | F11: ='Debt & Capital'!F44 -> -3977277.8 | G11: ='Debt & Capital'!G44 -> -3508749.8 | H11: ='Debt & Capital'!H44 -> -3028956.9
B12: EBT | C12: =C10+C11 -> 0 | D12: =D10+D11 -> -81896.678 | E12: =E10+E11 -> 6268995.9 | F12: =F10+F11 -> 7110039.5 | G12: =G10+G11 -> 8066894.9 | H12: =H10+H11 -> 9039655
B14: Memo: EBITDA / interest (x) | C14: =IFERROR(-C7/C11,"n/a") -> n/a | D14: =IFERROR(-D7/D11,"n/a") -> 1.1509873 | E14: =IFERROR(-E7/E11,"n/a") -> 3.1656815 | F14: =IFERROR(-F7/F11,"n/a") -> 3.5372795 | G14: =IFERROR(-G7/G11,"n/a") -> 4.1454189 | H14: =IFERROR(-H7/H11,"n/a") -> 4.9517446

Sheet Debt & Capital
B1: CAPITAL STACK, SOURCES & USES, DEBT SCHEDULE
A3: SOURCES OF FUNDS
B4: Fund equity — Class B preferred (Reg D 506(c)) | D4: =Assumptions!C33 -> 10000000
B5: Membership equity — founding members | D5: =Assumptions!C34 -> 10000000
B6: Outside equity — direct 15% of Chicago West | D6: =Assumptions!C35 -> 5000000
B7: Bank senior term loan | D7: =Assumptions!C37 -> 40000000
B8: Equipment / leasing facility | D8: =Assumptions!C39 -> 12000000
B9: Total sources | D9: =SUM(D4:D8) -> 77000000
A11: USES OF FUNDS
B12: Buildings and domes (four domes) | D12: 47567802
B13: Course layout | D13: 8396438
B14: Property (land) | D14: 5650000
B15: Contingency (10% of fixed assets) | D15: 6203674
B16: Financing fees & expenses | D16: 2800000
B17: Furniture & fixtures | D17: 200000
B18: Machinery & equipment | D18: 172500
B19: Initial inventory | D19: 150000
B20: Website development (capitalized) | D20: 150000
B21: Computer equipment | D21: 50000
B22: Marketing & studies (capitalized) | D22: 550000
B23: Working capital + 12-mo interest reserve (plug) | D23: =D9-SUM(D12:D22) -> 5109586
B24: Total uses | D24: =SUM(D12:D23) -> 77000000
B25: Surplus / (shortfall) | D25: =D9-D24 -> 0
A27: BANK SENIOR DEBT SCHEDULE (interest-only FY2027–28, then amortizing)
B28: USD $ | C28: 2026 | D28: 2027 | E28: 2028 | F28: 2029 | G28: 2030 | H28: 2031
B29: Opening balance | C29: 0 | D29: =Assumptions!C37 -> 40000000 | E29: =D31 -> 40000000 | F29: =E31 -> 40000000 | G29: =F31 -> 36000000 | H29: =G31 -> 32000000
B30: Principal repayment | C30: 0 | D30: 0 | E30: 0 | F30: 4000000 | G30: 4000000 | H30: 4000000
B31: Closing balance | C31: =C29-C30 -> 0 | D31: =D29-D30 -> 40000000 | E31: =E29-E30 -> 40000000 | F31: =F29-F30 -> 36000000 | G31: =G29-G30 -> 32000000 | H31: =H29-H30 -> 28000000
B32: Interest expense (avg balance × rate) | C32: 0 | D32: =(D29+D31)/2*Assumptions!C38 -> 3360000 | E32: =(E29+E31)/2*Assumptions!C38 -> 3360000 | F32: =(F29+F31)/2*Assumptions!C38 -> 3192000 | G32: =(G29+G31)/2*Assumptions!C38 -> 2856000 | H32: =(H29+H31)/2*Assumptions!C38 -> 2520000
A34: EQUIPMENT / LEASING SCHEDULE (fully amortizing over term)
B35: USD $ | C35: 2026 | D35: 2027 | E35: 2028 | F35: 2029 | G35: 2030 | H35: 2031
B36: Opening balance | C36: 0 | D36: =Assumptions!C39 -> 12000000 | E36: =D40 -> 10675569 | F36: =E40 -> 9238562.1 | G36: =F40 -> 7679409.2 | H36: =G40 -> 5987728.3
B37: Annual payment (P+I) | C37: 0 | D37: =-PMT(Assumptions!C40,Assumptions!C41,Assumptions!C39) -> 2344430.7 | E37: =-PMT(Assumptions!C40,Assumptions!C41,Assumptions!C39) -> 2344430.7 | F37: =-PMT(Assumptions!C40,Assumptions!C41,Assumptions!C39) -> 2344430.7 | G37: =-PMT(Assumptions!C40,Assumptions!C41,Assumptions!C39) -> 2344430.7 | H37: =-PMT(Assumptions!C40,Assumptions!C41,Assumptions!C39) -> 2344430.7
B38: Interest portion | C38: 0 | D38: =D36*Assumptions!C40 -> 1020000 | E38: =E36*Assumptions!C40 -> 907423.39 | F38: =F36*Assumptions!C40 -> 785277.78 | G38: =G36*Assumptions!C40 -> 652749.78 | H38: =H36*Assumptions!C40 -> 508956.91
B39: Principal portion | C39: 0 | D39: =D37-D38 -> 1324430.7 | E39: =E37-E38 -> 1437007.3 | F39: =F37-F38 -> 1559152.9 | G39: =G37-G38 -> 1691680.9 | H39: =H37-H38 -> 1835473.7
B40: Closing balance | C40: =C36-C39 -> 0 | D40: =D36-D39 -> 10675569 | E40: =E36-E39 -> 9238562.1 | F40: =F36-F39 -> 7679409.2 | G40: =G36-G39 -> 5987728.3 | H40: =H36-H39 -> 4152254.6
A42: COMBINED DEBT SERVICE
B43: USD $ | C43: 2026 | D43: 2027 | E43: 2028 | F43: 2029 | G43: 2030 | H43: 2031
B44: Total interest expense (bank + lease) | C44: =-(C32+C38) -> 0 | D44: =-(D32+D38) -> -4380000 | E44: =-(E32+E38) -> -4267423.4 | F44: =-(F32+F38) -> -3977277.8 | G44: =-(G32+G38) -> -3508749.8 | H44: =-(H32+H38) -> -3028956.9
B45: Total debt outstanding (closing) | C45: =C31+C40 -> 0 | D45: =D31+D40 -> 50675569 | E45: =E31+E40 -> 49238562 | F45: =F31+F40 -> 43679409 | G45: =G31+G40 -> 37987728 | H45: =H31+H40 -> 32152255
...

Sheet Returns
B1: INVESTOR RETURNS — MULTI-TRANCHE WATERFALL
B2: Exit value flows live from Year-5 EBITDA × exit multiple. Pool = Fund + Membership ($20M, 10% pref). Outside = direct 15% stake. Above-pref split 50/50 investor pool / Manager. Illustrative — final waterfall per offering documents (Bond Conway).
A4: EXIT VALUATION (FY2031)
B5: Year-5 (FY2031) EBITDA | C5: ='P&L'!H7 -> 14998621
B6: Exit EBITDA multiple | C6: =Assumptions!C60 -> 9
B7: Total enterprise value (TEV) | C7: =C5*C6 -> 1.3498759e+08
B8: Less: net debt at exit | C8: =-Assumptions!C63 -> -32152255
B9: Equity value at exit | C9: =C7+C8 -> 1.0283533e+08
A11: EXIT EQUITY BY CLASS
B12: Class / tranche | D12: Share | F12: Value at exit
B13: Fund — Class B preferred ($10M) | D13: =Assumptions!C52 -> 0.25 | F13: =$C$9*D13 -> 25708833
B14: Membership equity ($10M) | D14: =Assumptions!C53 -> 0.1 | F14: =$C$9*D14 -> 10283533
B15: Outside — direct stake ($5M) | D15: =Assumptions!C54 -> 0.125 | F15: =$C$9*D15 -> 12854417
B16: Manager — Class A (carry) | D16: =Assumptions!C55 -> 0.525 | F16: =$C$9*D16 -> 53988550
B17: Total | D17: =SUM(D13:D16) -> 1 | F17: =SUM(F13:F16) -> 1.0283533e+08
A19: PER-TRANCHE CASH FLOWS & RETURNS
B20: USD $ | C20: 2026 | D20: 2027 | E20: 2028 | F20: 2029 | G20: 2030 | H20: 2031
B21: Fund — net cash flow ($10M) | C21: =-Assumptions!C33 -> -10000000 | D21: 0 | E21: =Assumptions!C33*Assumptions!C46 -> 1000000 | F21: =Assumptions!C33*Assumptions!C46 -> 1000000 | G21: =Assumptions!C33*Assumptions!C46 -> 1000000 | H21: =Assumptions!C33*Assumptions!C46*2+F13 -> 27708833
B22: Membership — net cash flow ($10M) | C22: =-Assumptions!C34 -> -10000000 | D22: 0 | E22: =Assumptions!C34*Assumptions!C46 -> 1000000 | F22: =Assumptions!C34*Assumptions!C46 -> 1000000 | G22: =Assumptions!C34*Assumptions!C46 -> 1000000 | H22: =Assumptions!C34*Assumptions!C46*2+F14 -> 12283533
B23: Strategic/Outside — net cash flow ($5M) | C23: =-Assumptions!C35 -> -5000000 | D23: 0 | E23: 0 | F23: 0 | G23: 0 | H23: =F15 -> 12854417
B24: Blended — all investor equity ($25M) | C24: =C21+C22+C23 -> -25000000 | D24: =D21+D22+D23 -> 0 | E24: =E21+E22+E23 -> 2000000 | F24: =F21+F22+F23 -> 2000000 | G24: =G21+G22+G23 -> 2000000 | H24: =H21+H22+H23 -> 52846783
A26: RETURN METRICS (modeled)
B27: Fund — net IRR / MOIC | C27: =IRR(C21:H21) -> 0.26670966 | D27: =SUM(D21:H21)/-C21 -> 3.0708833
B28: Membership — net IRR / MOIC | C28: =IRR(C22:H22) -> 0.097265121 | D28: =SUM(D22:H22)/-C22 -> 1.5283533
B29: Strategic/Outside — net IRR / MOIC | C29: =IRR(C23:H23) -> 0.20785965 | D29: =SUM(D23:H23)/-C23 -> 2.5708833
B30: Blended — net IRR / MOIC | C30: =IRR(C24:H24) -> 0.19742363 | D30: =SUM(D24:H24)/-C24 -> 2.3538713
B31: MEGALODOME GOLF USA INC. (Manager) value at exit | C31: =F16 -> 53988550
B32: Total investor preferred + PIK (Fund+Memb) | C32: =(Assumptions!C33+Assumptions!C34)*Assumptions!C46*5 -> 10000000
B33: Note: MEG USA upside (equity in parent) additional, unquantified.

Sheet Sensitivity
B1: SENSITIVITY & SCENARIO ANALYSIS
B2: Two dominant levers: exit multiple and Year-5 EBITDA. Investor share of exit equity = Fund + Membership + Outside (57.5%).
A4: TABLE 1 — All-investor exit value & blended MOIC vs. exit multiple
B5: Exit EBITDA multiple | C5: 7 | D5: 7.5 | E5: 8 | F5: 8.5 | G5: 9 | H5: 9.5
B6: Equity value at exit | C6: ='P&L'!$H$7*C$5-Assumptions!C63 -> 72838092 | D6: ='P&L'!$H$7*D$5-Assumptions!C63 -> 80337402 | E6: ='P&L'!$H$7*E$5-Assumptions!C63 -> 87836712 | F6: ='P&L'!$H$7*F$5-Assumptions!C63 -> 95336023 | G6: ='P&L'!$H$7*G$5-Assumptions!C63 -> 1.0283533e+08 | H6: ='P&L'!$H$7*H$5-Assumptions!C63 -> 1.1033464e+08
B7: Investor exit value (57.5%) | C7: =C6*(Assumptions!C52+Assumptions!C53+Assumptions!C54) -> 34598094 | D7: =D6*(Assumptions!C52+Assumptions!C53+Assumptions!C54) -> 38160266 | E7: =E6*(Assumptions!C52+Assumptions!C53+Assumptions!C54) -> 41722438 | F7: =F6*(Assumptions!C52+Assumptions!C53+Assumptions!C54) -> 45284611 | G7: =G6*(Assumptions!C52+Assumptions!C53+Assumptions!C54) -> 48846783 | H7: =H6*(Assumptions!C52+Assumptions!C53+Assumptions!C54) -> 52408956
B8: Approx. blended MOIC to investors | C8: =((Assumptions!C33+Assumptions!C34)*Assumptions!C46*5+C7)/(Assumptions!C33+Assumptions!C34+Assumptions!C35) -> 1.7839237 | D8: =((Assumptions!C33+Assumptions!C34)*Assumptions!C46*5+D7)/(Assumptions!C33+Assumptions!C34+Assumptions!C35) -> 1.9264106 | E8: =((Assumptions!C33+Assumptions!C34)*Assumptions!C46*5+E7)/(Assumptions!C33+Assumptions!C34+Assumptions!C35) -> 2.0688975 | F8: =((Assumptions!C33+Assumptions!C34)*Assumptions!C46*5+F7)/(Assumptions!C33+Assumptions!C34+Assumptions!C35) -> 2.2113844 | G8: =((Assumptions!C33+Assumptions!C34)*Assumptions!C46*5+G7)/(Assumptions!C33+Assumptions!C34+Assumptions!C35) -> 2.3538713 | H8: =((Assumptions!C33+Assumptions!C34)*Assumptions!C46*5+H7)/(Assumptions!C33+Assumptions!C34+Assumptions!C35) -> 2.4963582
A10: TABLE 2 — Scenarios (per business plan stress cases)
B11: Scenario | C11: Year-1 realization | D11: Exit multiple | E11: Year-5 EBITDA | F11: Investor exit value | G11: Approx. MOIC
B12: Downside | C12: 0.35 | D12: 7 | E12: ='P&L'!H7 -> 14998621 | F12: =(E12*D12-Assumptions!C63)*(Assumptions!C52+Assumptions!C53+Assumptions!C54) -> 34598094 | G12: =((Assumptions!C33+Assumptions!C34)*Assumptions!C46*5+F12)/(Assumptions!C33+Assumptions!C34+Assumptions!C35) -> 1.7839237
B13: Base case | C13: 0.379 | D13: 9 | E13: ='P&L'!H7 -> 14998621 | F13: =(E13*D13-Assumptions!C63)*(Assumptions!C52+Assumptions!C53+Assumptions!C54) -> 48846783 | G13: =((Assumptions!C33+Assumptions!C34)*Assumptions!C46*5+F13)/(Assumptions!C33+Assumptions!C34+Assumptions!C35) -> 2.3538713
B14: Upside | C14: 0.5 | D14: 10 | E14: ='P&L'!H7 -> 14998621 | F14: =(E14*D14-Assumptions!C63)*(Assumptions!C52+Assumptions!C53+Assumptions!C54) -> 55971128 | G14: =((Assumptions!C33+Assumptions!C34)*Assumptions!C46*5+F14)/(Assumptions!C33+Assumptions!C34+Assumptions!C35) -> 2.6388451
B16: Note: scenarios vary the two dominant levers. Year-1 realization affects ramp cash but not stabilized Year-5 EBITDA, which drives exit value. Interim pool preferred is held at modeled levels. A full multi-variable sensitivity should accompany investor distribution per the business plan.
